{"name": "test_login", "status": "broken", "statusDetails": {"message": "TypeError: get_screenshot_as_file() got an unexpected keyword argument 'executable_path'", "trace": "self = <test_login_i.TestLogin object at 0x10481b640>\n\n    def test_login(self):\n        try:\n            driver = self.driver\n            driver.get(utils.URL)\n            login = LoginPage(driver)\n            login.enter_username(utils.USERNAME)\n            login.enter_password(utils.PASSWORD)\n            login.click_login()\n            time.sleep(4)\n            home_page = driver.title\n>           assert home_page == \"Course Materials | Pearson1\"\nE           AssertionError: assert 'Course Materials | Pearson' == 'Course Materials | Pearson1'\nE             - Course Materials | Pearson\nE             + Course Materials | Pearson1\nE             ?                           +\n\nTests/Instructor/test_login_i.py:34: AssertionError\n\nDuring handling of the above exception, another exception occurred:\n\nself = <test_login_i.TestLogin object at 0x10481b640>\n\n    def test_login(self):\n        try:\n            driver = self.driver\n            driver.get(utils.URL)\n            login = LoginPage(driver)\n            login.enter_username(utils.USERNAME)\n            login.enter_password(utils.PASSWORD)\n            login.click_login()\n            time.sleep(4)\n            home_page = driver.title\n            assert home_page == \"Course Materials | Pearson1\"\n    \n        except AssertionError as error:\n            print(\"Assertion error occurred\")\n            print(error)\n            curr_time = moment.now().strftime(\"%m-%d-%Y_%H-%M-%S_\")\n            test_name = utils.whoami()\n            screenshot_name = str(test_name) + \"_\" + curr_time\n            allure.attach(self.driver.get_screenshot_as_png(), name=screenshot_name,\n                          attachment_type=allure.attachment_type.PNG)\n>           driver.get_screenshot_as_file(executable_path=\"/Users/vburiol/PycharmProjects/GLP_Test/Screenshots\" + screenshot_name\n                                               + \".png\")\nE           TypeError: get_screenshot_as_file() got an unexpected keyword argument 'executable_path'\n\nTests/Instructor/test_login_i.py:44: TypeError"}, "attachments": [{"name": "40_01-27-2020_11-00-25_", "source": "78927e79-9e8b-433d-9352-f3ee7dd51cb5-attachment.png", "type": "image/png"}, {"name": "stdout", "source": "86b1a480-c007-47fb-b7b8-0a0cb79e33c6-attachment.txt", "type": "text/plain"}], "start": 1580151617216, "stop": 1580151625568, "uuid": "785dd1ad-d33d-4772-94a6-9950a85bc2ad", "historyId": "c31cf62fa6afeb23e503055889de484c", "testCaseId": "d3caa846cd5ed721ded9a3a35783b148", "fullName": "Tests.Instructor.test_login_i.TestLogin#test_login", "labels": [{"name": "parentSuite", "value": "Tests.Instructor"}, {"name": "suite", "value": "test_login_i"}, {"name": "subSuite", "value": "TestLogin"}, {"name": "host", "value": "SNFCAML-X0FJG3Q"}, {"name": "thread", "value": "42488-MainThread"}, {"name": "framework", "value": "pytest"}, {"name": "language", "value": "cpython3"}, {"name": "package", "value": "Tests.Instructor.test_login_i"}]}